Workbook

Sheet OFP
A1: Mass & Balance | J1: FUEL REQUIREMENTS | Z1: {=IF(OFP!N16="", "", _xlfn.LET(_xlpm.RowData, _xlfn._xlws.FILTER(NavData!C:J, NavData!A:A=OFP!N16, ""), _xlpm.AllRunways, _xlfn.CHOOSECOLS(_xlfn.WRAPROWS(_xlpm.RowData, 2), 1), _xlfn._xlws.FILTER(_xlpm.AllRunways, _xlpm.AllRunways<>"")))} -> 10
A2: LN-TRB | D2: Weight (lbs) | E2: Arm Aft Datum (in) | G2: Moment (in-lbs) | M2: US Gallons | N2: Pounds(lbs) | O2: Time (hh:mm) | Z2: 28
A3: Basic Empty Mass | D3: =VLOOKUP(OFP!A2,'AC REG'!A:C, 2, FALSE) -> 2020.3 | E3: =IFERROR(G3/D3,0) -> 38.982428 | G3: =VLOOKUP(A2,'AC REG'!A:C,3,FALSE) -> 78756.2 | J3: Trip fuel (incl 1,7 for startup,taxi.. | M3: =(O3*24)*P4+1.7 -> 34 | N3: =M3*6 -> 204 | O3: 0.11215278 | P3: FUEL FLOW | Y3: ikke rør
A4: Pilot - Left Seat | D4: 170 | E4: 37 | G4: =D4*E4 -> 6290 | J4: Alternate Fuel | M4: 6 | N4: =M4*6 -> 36 | O4: =M4/P4/24 -> 0.020833333 | P4: 12 | R4: Speeds
A5: Pilot or passenger - Right Seat | D5: 0 | E5: 37 | G5: =D5*E5 -> 0 | J5: Contingency Fuel | R5: Vx | S5: 65
A6: Rear passengers | D6: 0 | E6: 74 | G6: =D6*E6 -> 0 | J6: Final Reserve | M6: =(O6*24)*P4 -> 12 | N6: =M6*6 -> 72 | O6: 0.041666667 | R6: Vy | S6: 80
A7: Fuel | D7: =N8 -> 384 | E7: 46.5 | G7: =D7*E7 -> 17856 | J7: Total Fuel Required | M7: =SUM(M3:M6) -> 52 | N7: =M7*6 -> 312 | O7: =SUM(O3:O6) -> 0.17465278 | R7: Va 3100 | S7: 110
A8: Baggage Area A | D8: 7.3 | E8: 97 | G8: =D8*E8 -> 708.1 | J8: Total Fuel Onboard | M8: 64 | N8: =M8*6 -> 384 | R8: 2600 | S8: 101
A9: Baggage Area B | D9: =VLOOKUP(A2,'AC REG'!A:D,4,FALSE) -> 0 | E9: 116 | G9: =D9*E9 -> 0 | J9: Endurance(incl final reserve) | N9: -----------> | O9: =(M8/P4)/24 -> 0.22222222 | R9: 2100 | S9: 91
A10: Baggage Area C | D10: 0.7 | E10: 129 | G10: =D10*E10 -> 90.3 | R10: Vno | S10: 140
A11: Total Takeoff Mass | D11: =SUM(D3:D10) -> 2582.3 | E11: =IFERROR(ROUND(G11/D11,1),0) -> 40.2 | G11: =SUM(G3:G10) -> 103700.6 | N11: Approach | R11: Va | S11: =110-(((3100-D14)*9)/500) -> 97.0094
A12: Enroute Fuel Consumed | D12: =N3 -> 204 | E12: 46.5 | G12: =D12*E12 -> 9486 | N12: Min FLT | R12: Vglide | S12: =ROUND(76-(((3100-D11)*6)/500),0) -> 70
A13: Last Minute Change | N13: =IF((D11>2950),((D11-2950)/6)/P4/24,0) -> 0
A14: Total Landing Mass | D14: =D11-D12 -> 2378.3 | E14: =G14/D14 -> 39.614262 | G14: =G11-G12 -> 94214.6
A15: Zero Fuel Mass | D15: =D11-D7 -> 2198.3 | E15: =G15/D15 -> 39.050448 | G15: =G11-G7 -> 85844.6 | K15: trykk på tallet for å velge rwy | N15: skriv her
C16: DO NOT TOUCH CELLS WITH BLUE MARKINGS | J16: AERODROME | N16: endu | Q16: MAN AERODROME OVERRIDE | T16: Use if METAR unavailable
C17: Ekstra baggasje kan plusses på i formellinjen over | J17: RWY | K17: 10 | M17: Elevation | N17: =IF(N16="", "", _xlfn.XLOOKUP(N16, NavData!$A:$A, NavData!$B:$B, "")) -> 254 | O17: Flaps | P17: 20° | Q17: W/V
C18: Hvis formler blir overskrevet / ting blir ødelagt, last ned på nytt fra epost | J18: RWY HDG | K18: {=IF(K17="", "", _xlfn.LET(_xlpm.RowData, _xlfn._xlws.FILTER(NavData!C:J, NavData!A:A=N16, ""), _xlpm.PairedData, _xlfn.WRAPROWS(_xlpm.RowData, 2), _xlfn.XLOOKUP(K17, _xlfn.CHOOSECOLS(_xlpm.PairedData, 1), _xlfn.CHOOSECOLS(_xlpm.PairedData, 2), "")))} -> 99 | M18: XWIND | N18: =IF(K19="VRB", L19, _xlfn.LET(_xlpm.RawXWC, L19 * SIN(RADIANS(K18-K19)), _xlpm.RoundedXWC, ROUND(ABS(_xlpm.RawXWC), 0), IF(_xlpm.RoundedXWC = 0, "0", _xlpm.RoundedXWC & IF(_xlpm.RawXWC > 0, "L", "R")))) -> 3L | O18: Press ALT | P18: =N17+(27*(1013-K20)) -> 875 | Q18: QNH
C19: Hvis klokka er satt til AM/PM på enheten vil det vises i tidene | J19: W/V | K19: =IF(ISNUMBER(R17), R17, IFERROR(VALUE(MID(J21, SEARCH("Z ", J21) + 2, 3)), "VRB")) -> 20 | L19: =IF(ISNUMBER(S17), S17, VALUE(MID(J21, SEARCH("Z ", J21) + 5, 2))) -> 3 | M19: WCOMP | N19: =IF(K19="VRB", L19*-1, _xlfn.LET(_xlpm.RawHWC, L19 * COS(RADIANS(K18-K19)), _xlpm.RoundedHWC, ROUND(ABS(_xlpm.RawHWC), 0), IF(_xlpm.RoundedHWC = 0, "0", _xlpm.RoundedHWC & IF(_xlpm.RawHWC > 0, "HW", "TW")))) -> 1HW | O19: Dens ALT | P19: =ROUND(P18 + (120 * (N20 - (15 - (2 * (P18 / 1000))))), 0) -> 605 | Q19: Temp.
C20: METAR kalkulasjoner fungerer kun på PC, autometar fungerer ikke | J20: QNH | K20: =IF(ISNUMBER(R18), R18, VALUE(MID(J21, SEARCH(" Q", J21)+2, 4))) -> 990 | M20: Temp. | N20: =IF(ISNUMBER(R19), R19, VALUE(SUBSTITUTE(TRIM(MID(J21, SEARCH("/", J21)-3, 3)), "M", "-"))) -> 11
C21: Noe kan være unøyaktig, lurt å dobbeltsjekke | J21: =IF(N16="", "", IFERROR(_xlfn.WEBSERVICE("https://aviationweather.gov/api/data/metar?ids="&N16), "METAR UNAVAIL")) -> METAR ENDU 201150Z 02003KT 350V080 9999 FEW040 BKN055 11/05 Q0990 NOSIG RMK WIND 1374FT 33005KT WIND 2165FT 33007KT
J24: Uncorrected take-off distance | O24: {=(CALC_TOD(D11,P18,N20))/3.28} -> 320.73171 | Q24: Uncorrected landing distance | V24: {=(CALC_LDG(P18,N20))/3.28} -> 416.15854
J25: H-Wind | K25: =IF(K19="VRB", 0, ROUND(L19*COS(RADIANS(K18-K19)), 0)) -> 1 | L25: Wind correction (no corr. Below 9 kts: | O25: =_xlfn.LET(_xlpm.Uncorr, O24, _xlpm.Wind, K25, _xlpm.HW_Corr, IF(_xlpm.Wind<9, 0, (_xlpm.Wind/9)*0.1), _xlpm.TW_Corr, (ABS(_xlpm.Wind)/2)*0.1, _xlpm.Multiplier, IF(_xlpm.Wind>=0, 1-_xlpm.HW_Corr, IF(_xlpm.Wind>=-10, 1+_xlpm.TW_Corr, "LIMIT")), IF(_xlpm.Multiplier="LIMIT", "LIMIT OVERRIDE", ROUND((_xlpm.Uncorr*_xlpm.Multiplier) - _xlpm.Uncorr, 0))) -> 0 | Q25: H-Wind | R25: =IF(K19="VRB", N19, ROUND(L19*COS(RADIANS(K18-K19)), 0)) -> 1 | S25: Wind correction (acc. To POH) | V25: =_xlfn.LET(_xlpm.Uncorr, V24, _xlpm.Wind, R25, _xlpm.HW_Corr, IF(_xlpm.Wind<9, 0, (_xlpm.Wind/9)*0.1), _xlpm.TW_Corr, (ABS(_xlpm.Wind)/2)*0.1, _xlpm.Multiplier, IF(_xlpm.Wind>=0, 1-_xlpm.HW_Corr, IF(_xlpm.Wind>=-10, 1+_xlpm.TW_Corr, "LIMIT")), IF(_xlpm.Multiplier="LIMIT", "LIMIT OVERRIDE", ROUND((_xlpm.Uncorr*_xlpm.Multiplier) - _xlpm.Uncorr, 0))) -> 0
L26: Brk action | M26: 6 | N26: Correction | O26: {=_xlfn.LET(_xlpm.WindCorrDist, O24 + O25, _xlpm.BA, M26, _xlpm.Multiplier, _xlfn.SWITCH(_xlpm.BA, 6, 1, 5, 1, 4, 1.1, 3, 1.2, 2, 1.5, 1, 2, 0, "PROHIBITED", "INVALID"), IF(_xlpm.Multiplier="PROHIBITED", "PROHIBITED", IF(_xlpm.Multiplier="INVALID", "ENTER BA 0-6", ROUND((_xlpm.WindCorrDist * _xlpm.Multiplier) - _xlpm.WindCorrDist, 0))))} -> 0 | S26: Brk Action | T26: 6 | U26: Correction | V26: {=_xlfn.LET(_xlpm.WindCorrDist, V24 + V25, _xlpm.BA, T26, _xlpm.Multiplier, _xlfn.SWITCH(_xlpm.BA, 6, 1, 5, 1, 4, 1.1, 3, 1.2, 2, 1.5, 1, 2, 0, "PROHIBITED", "INVALID"), IF(_xlpm.Multiplier="PROHIBITED", "PROHIBITED", IF(_xlpm.Multiplier="INVALID", "ENTER BA 0-6", ROUND((_xlpm.WindCorrDist * _xlpm.Multiplier) - _xlpm.WindCorrDist, 0))))} -> 0
J27: Fill out As Required | Q27: Fill out As Required
J30: Corrected take-off distance | O30: =SUM(O24:O29) -> 320.73171 | Q30: Corrected landing distance | V30: =SUM(V24:V29) -> 416.15854
J31: Performance factor | L31: 0.25 | M31: Required take-off distance | O31: =ROUND(O30 * (1 + L31), 0) -> 401 | Q31: Performance factor | S31: 0.43 | T31: Required landing distance | V31: =ROUND(V30 * (1 + S31), 0) -> 595
N32: TODA | O32: =_xlfn.XLOOKUP(TRIM(N16)&TRIM(K17), NavData!U:U, NavData!R:R, "RWY NOT FOUND") -> 2443 | U32: LDA | V32: =_xlfn.XLOOKUP(TRIM(N16)&TRIM(K17), NavData!U:U, NavData!T:T, "RWY NOT FOUND") -> 2001
O34: TO/LDG dist limitations: Max pressure alt 5000ft Max temp 40°C
J37: ZFM = Zero Fuel Mass

Sheet Performance
A1: Weight | B1: PA | C1: Temp | D1: Dist | F1: PA | G1: TEMP | H1: DIST | P1: standard | Q1: ARM | R1: WEIGHT | S1: autopilot | T1: ARM | U1: WEIGHT | V1: mlaw | W1: ARM | X1: WEIGHT | Z1: 20MP 2200RPM | AA1: Alt | AB1: Temp -20 | AC1: Temp Std | AD1: Temp +20 | AE1: TAS -20 | AF1: TAS Std | AG1: TAS +20 | AH1: GPH -20 | AI1: GPH Std | AJ1: GPH +20
A2: 3100 | B2: 0 | C2: 0 | D2: 1365 | F2: 0 | G2: 0 | H2: 1300 | Q2: 33 | R2: 1800 | T2: 34 | U2: 1800 | W2: 39 | X2: 2950 | AA2: 0 | AB2: -5 | AC2: 15 | AD2: 35 | AE2: 114 | AF2: 114 | AG2: 114 | AH2: 10.2 | AI2: 9.9 | AJ2: 9.7
A3: 3100 | B3: 0 | C3: 10 | D3: 1460 | F3: 0 | G3: 10 | H3: 1335 | Q3: 33 | R3: 2225 | T3: 34 | U3: 2400 | W3: 46 | X3: 2950 | AA3: 2000 | AB3: -9 | AC3: 11 | AD3: 31 | AE3: 118 | AF3: 118 | AG3: 118 | AH3: 10.5 | AI3: 10.2 | AJ3: 9.9
A4: 3100 | B4: 0 | C4: 20 | D4: 1570 | F4: 0 | G4: 20 | H4: 1365 | Q4: 35.8 | R4: 2700 | AA4: 4000 | AB4: -13 | AC4: 7 | AD4: 27 | AE4: 122 | AF4: 122 | AG4: 121 | AH4: 10.7 | AI4: 10.4 | AJ4: 10.2
A5: 3100 | B5: 0 | C5: 30 | D5: 1680 | F5: 0 | G5: 30 | H5: 1400 | Q5: 41 | R5: 3100 | AA5: 6000 | AB5: -17 | AC5: 3 | AD5: 23 | AE5: 126 | AF5: 126 | AG5: 125 | AH5: 11 | AI5: 10.7 | AJ5: 10.4
A6: 3100 | B6: 0 | C6: 40 | D6: 1800 | F6: 0 | G6: 40 | H6: 1435 | Q6: 46 | R6: 3100 | AA6: 8000 | AB6: -21 | AC6: -1 | AD6: 19 | AE6: 130 | AF6: 130 | AG6: 129 | AH6: 11.3 | AI6: 11 | AJ6: 10.7
A7: 3100 | B7: 1000 | C7: 0 | D7: 1490 | F7: 1000 | G7: 0 | H7: 1335 | Q7: 46 | R7: 1800 | AA7: 10000 | AB7: -25 | AC7: -5 | AD7: 15 | AE7: 134 | AF7: 134 | AG7: 133 | AH7: 11.6 | AI7: 11.3 | AJ7: 10.9
A8: 3100 | B8: 1000 | C8: 10 | D8: 1600 | F8: 1000 | G8: 10 | H8: 1365 | Q8: 33 | R8: 1800 | Z8: 18MP 2200RPM | AA8: 12000 | AB8: -29 | AC8: -9 | AD8: 11 | AE8: 128 | AF8: 128 | AG8: 127 | AH8: 10.6 | AI8: 10.3 | AJ8: 10
A9: 3100 | B9: 1000 | C9: 20 | D9: 1720 | F9: 1000 | G9: 20 | H9: 1400 | P9: DONT TOUCH | R9: USED FOR CG CALCS | Z9: 16MP 2200RPM | AA9: 14000 | AB9: -33 | AC9: -13 | AD9: 7 | AE9: 120 | AF9: 119 | AG9: 118 | AH9: 9.6 | AI9: 9.3 | AJ9: 9
A10: 3100 | B10: 1000 | C10: 30 | D10: 1845 | F10: 1000 | G10: 30 | H10: 1440
A11: 3100 | B11: 1000 | C11: 40 | D11: 1980 | F11: 1000 | G11: 40 | H11: 1475
A12: 3100 | B12: 2000 | C12: 0 | D12: 1635 | F12: 2000 | G12: 0 | H12: 1370
A13: 3100 | B13: 2000 | C13: 10 | D13: 1760 | F13: 2000 | G13: 10 | H13: 1405
A14: 3100 | B14: 2000 | C14: 20 | D14: 1890 | F14: 2000 | G14: 20 | H14: 1440
A15: 3100 | B15: 2000 | C15: 30 | D15: 2035 | F15: 2000 | G15: 30 | H15: 1480
A16: 3100 | B16: 2000 | C16: 40 | D16: 2190 | F16: 2000 | G16: 40 | H16: 1515
A17: 3100 | B17: 3000 | C17: 0 | D17: 1800 | F17: 3000 | G17: 0 | H17: 1410
A18: 3100 | B18: 3000 | C18: 10 | D18: 1940 | F18: 3000 | G18: 10 | H18: 1445
A19: 3100 | B19: 3000 | C19: 20 | D19: 2090 | F19: 3000 | G19: 20 | H19: 1485
A20: 3100 | B20: 3000 | C20: 30 | D20: 2255 | F20: 3000 | G20: 30 | H20: 1525
A21: 3100 | B21: 3000 | C21: 40 | D21: 2435 | F21: 3000 | G21: 40 | H21: 1560
... A31: 3100 | B31: 5000 | C31: 40 | D31: 3070 | F31: 5000 | G31: 40 | H31: 1650
A32: 2700 | B32: 0 | C32: 0 | D32: 995
A33: 2700 | B33: 0 | C33: 10 | D33: 1065
A34: 2700 | B34: 0 | C34: 20 | D34: 1135
A35: 2700 | B35: 0 | C35: 30 | D35: 1215
A36: 2700 | B36: 0 | C36: 40 | D36: 1295
A37: 2700 | B37: 1000 | C37: 0 | D37: 1080
A38: 2700 | B38: 1000 | C38: 10 | D38: 1155
A39: 2700 | B39: 1000 | C39: 20 | D39: 1235
A40: 2700 | B40: 1000 | C40: 30 | D40: 1320
A41: 2700 | B41: 1000 | C41: 40 | D41: 1410
A42: 2700 | B42: 2000 | C42: 0 | D42: 1180
A43: 2700 | B43: 2000 | C43: 10 | D43: 1260
... A91: 2300 | B91: 5000 | C91: 40 | D91: 1390

Sheet NavData
A1: ICAO | B1: AD ELEV | C1: RWY1 | D1: HDG1 | E1: RWY2 | F1: HDG2 | G1: RWY3 | H1: HDG3 | I1: RWY4 | J1: HDG4 | O1: ICAO | P1: RWY | Q1: TORA (M) | R1: ASDA (M) | S1: TODA (M) | T1: LDA (M)
A2: ENAT | B2: 10 | C2: 11 | D2: 109 | E2: =IF(C2="", "", _xlfn.LET( _xlpm.Num, VALUE(LEFT(C2, 2)), _xlpm.Letter, IF(ISNUMBER(VALUE(RIGHT(C2, 1))), "", RIGHT(C2, 1)), _xlpm.NewNum, IF(_xlpm.Num<=18, _xlpm.Num+18, _xlpm.Num-18), _xlpm.NewLetter, IF(_xlpm.Letter="L", "R", IF(_xlpm.Letter="R", "L", _xlpm.Letter)), TEXT(_xlpm.NewNum, "00") & _xlpm.NewLetter )) -> 29 | F2: =IF(D2="", "", IF(D2<=180, D2+180, D2-180)) -> 289 | O2: ENAT | P2: 11 | Q2: 2127 | R2: 2127 | S2: 2277 | T2: 1851 | U2: =TRIM(O2) & TRIM(P2) -> ENAT11
A3: ENAN | B3: 30 | C3: 14 | D3: 140 | E3: =IF(C3="", "", _xlfn.LET( _xlpm.Num, VALUE(LEFT(C3, 2)), _xlpm.Letter, IF(ISNUMBER(VALUE(RIGHT(C3, 1))), "", RIGHT(C3, 1)), _xlpm.NewNum, IF(_xlpm.Num<=18, _xlpm.Num+18, _xlpm.Num-18), _xlpm.NewLetter, IF(_xlpm.Letter="L", "R", IF(_xlpm.Letter="R", "L", _xlpm.Letter)), TEXT(_xlpm.NewNum, "00") & _xlpm.NewLetter )) -> 32 | F3: =IF(D3="", "", IF(D3<=180, D3+180, D3-180)) -> 320 | O3: ENAT | P3: 29 | Q3: 2123 | R3: 2123 | S3: 2273 | T3: 1907 | U3: =TRIM(O3) & TRIM(P3) -> ENAT29
A4: ENGK | B4: 415 | C4: 05 | D4: 50 | E4: =IF(C4="", "", _xlfn.LET( _xlpm.Num, VALUE(LEFT(C4, 2)), _xlpm.Letter, IF(ISNUMBER(VALUE(RIGHT(C4, 1))), "", RIGHT(C4, 1)), _xlpm.NewNum, IF(_xlpm.Num<=18, _xlpm.Num+18, _xlpm.Num-18), _xlpm.NewLetter, IF(_xlpm.Letter="L", "R", IF(_xlpm.Letter="R", "L", _xlpm.Letter)), TEXT(_xlpm.NewNum, "00") & _xlpm.NewLetter )) -> 23 | F4: =IF(D4="", "", IF(D4<=180, D4+180, D4-180)) -> 230 | O4: ENAN | P4: 14 | Q4: 1839 | R4: 1839 | S4: 1839 | T4: 1839 | U4: =TRIM(O4) & TRIM(P4) -> ENAN14
A5: ENDU | B5: 254 | C5: 10 | D5: 99 | E5: =IF(C5="", "", _xlfn.LET( _xlpm.Num, VALUE(LEFT(C5, 2)), _xlpm.Letter, IF(ISNUMBER(VALUE(RIGHT(C5, 1))), "", RIGHT(C5, 1)), _xlpm.NewNum, IF(_xlpm.Num<=18, _xlpm.Num+18, _xlpm.Num-18), _xlpm.NewLetter, IF(_xlpm.Letter="L", "R", IF(_xlpm.Letter="R", "L", _xlpm.Letter)), TEXT(_xlpm.NewNum, "00") & _xlpm.NewLetter )) -> 28 | F5: =IF(D5="", "", IF(D5<=180, D5+180, D5-180)) -> 279 | O5: ENAN | P5: 32 | Q5: 1989 | R5: 1989 | S5: 2437 | T5: 1839 | U5: =TRIM(O5) & TRIM(P5) -> ENAN32
A6: ENBR | B6: 171 | C6: 17 | D6: 169 | E6: =IF(C6="", "", _xlfn.LET( _xlpm.Num, VALUE(LEFT(C6, 2)), _xlpm.Letter, IF(ISNUMBER(VALUE(RIGHT(C6, 1))), "", RIGHT(C6, 1)), _xlpm.NewNum, IF(_xlpm.Num<=18, _xlpm.Num+18, _xlpm.Num-18), _xlpm.NewLetter, IF(_xlpm.Letter="L", "R", IF(_xlpm.Letter="R", "L", _xlpm.Letter)), TEXT(_xlpm.NewNum, "00") & _xlpm.NewLetter )) -> 35 | F6: =IF(D6="", "", IF(D6<=180, D6+180, D6-180)) -> 349 | O6: ENBL | P6: 07 | Q6: 931 | R6: 931 | S6: 1111 | T6: 870 | U6: =TRIM(O6) & TRIM(P6) -> ENBL07
A7: ENBV | B7: 43 | C7: 06 | D7: 59 | E7: =IF(C7="", "", _xlfn.LET( _xlpm.Num, VALUE(LEFT(C7, 2)), _xlpm.Letter, IF(ISNUMBER(VALUE(RIGHT(C7, 1))), "", RIGHT(C7, 1)), _xlpm.NewNum, IF(_xlpm.Num<=18, _xlpm.Num+18, _xlpm.Num-18), _xlpm.NewLetter, IF(_xlpm.Letter="L", "R", IF(_xlpm.Letter="R", "L", _xlpm.Letter)), TEXT(_xlpm.NewNum, "00") & _xlpm.NewLetter )) -> 24 | F7: =IF(D7="", "", IF(D7<=180, D7+180, D7-180)) -> 239 | O7: ENBL | P7: 25 | Q7: 980 | R7: 980 | S7: 1160 | T7: 890 | U7: =TRIM(O7) & TRIM(P7) -> ENBL25
A8: ENBO | B8: 44 | C8: 07 | D8: 70 | E8: =IF(C8="", "", _xlfn.LET( _xlpm.Num, VALUE(LEFT(C8, 2)), _xlpm.Letter, IF(ISNUMBER(VALUE(RIGHT(C8, 1))), "", RIGHT(C8, 1)), _xlpm.NewNum, IF(_xlpm.Num<=18, _xlpm.Num+18, _xlpm.Num-18), _xlpm.NewLetter, IF(_xlpm.Letter="L", "R", IF(_xlpm.Letter="R", "L", _xlpm.Letter)), TEXT(_xlpm.NewNum, "00") & _xlpm.NewLetter )) -> 25 | F8: =IF(D8="", "", IF(D8<=180, D8+180, D8-180)) -> 250 | O8: ENBN | P8: 03 | Q8: 1199 | R8: 1199 | S8: 1199 | T8: 1199 | U8: =TRIM(O8) & TRIM(P8) -> ENBN03
A9: ENBN | B9: 26 | C9: 03 | D9: 34 | E9: =IF(C9="", "", _xlfn.LET( _xlpm.Num, VALUE(LEFT(C9, 2)), _xlpm.Letter, IF(ISNUMBER(VALUE(RIGHT(C9, 1))), "", RIGHT(C9, 1)), _xlpm.NewNum, IF(_xlpm.Num<=18, _xlpm.Num+18, _xlpm.Num-18), _xlpm.NewLetter, IF(_xlpm.Letter="L", "R", IF(_xlpm.Letter="R", "L", _xlpm.Letter)), TEXT(_xlpm.NewNum, "00") & _xlpm.NewLetter )) -> 21 | F9: =IF(D9="", "", IF(D9<=180, D9+180, D9-180)) -> 214 | O9: ENBN | P9: 21 | Q9: 1199 | R9: 1199 | S9: 1560 | T9: 1199 | U9: =TRIM(O9) & TRIM(P9) -> ENBN21
A10: ENBS | B10: 490 | C10: 03 | D10: 28 | E10: =IF(C10="", "", _xlfn.LET( _xlpm.Num, VALUE(LEFT(C10, 2)), _xlpm.Letter, IF(ISNUMBER(VALUE(RIGHT(C10, 1))), "", RIGHT(C10, 1)), _xlpm.NewNum, IF(_xlpm.Num<=18, _xlpm.Num+18, _xlpm.Num-18), _xlpm.NewLetter, IF(_xlpm.Letter="L", "R", IF(_xlpm.Letter="R", "L", _xlpm.Letter)), TEXT(_xlpm.NewNum, "00") & _xlpm.NewLetter )) -> 21 | F10: =IF(D10="", "", IF(D10<=180, D10+180, D10-180)) -> 208 | O10: ENBO | P10: 07 | Q10: 2794 | R10: 2794 | S10: 3063 | T10: 2794 | U10: =TRIM(O10) & TRIM(P10) -> ENBO07
A11: ENFL | B11: 37 | C11: 07 | D11: 70 | E11: =IF(C11="", "", _xlfn.LET( _xlpm.Num, VALUE(LEFT(C11, 2)), _xlpm.Letter, IF(ISNUMBER(VALUE(RIGHT(C11, 1))), "", RIGHT(C11, 1)), _xlpm.NewNum, IF(_xlpm.Num<=18, _xlpm.Num+18, _xlpm.Num-18), _xlpm.NewLetter, IF(_xlpm.Letter="L", "R", IF(_xlpm.Letter="R", "L", _xlpm.Letter)), TEXT(_xlpm.NewNum, "00") & _xlpm.NewLetter )) -> 25 | F11: =IF(D11="", "", IF(D11<=180, D11+180, D11-180)) -> 250 | O11: ENBO | P11: 25 | Q11: 2794 | R11: 2794 | S11: 2794 | T11: 2794 | U11: =TRIM(O11) & TRIM(P11) -> ENBO25
A12: ENBL | B12: 1045 | C12: 07 | D12: 72 | E12: =IF(C12="", "", _xlfn.LET( _xlpm.Num, VALUE(LEFT(C12, 2)), _xlpm.Letter, IF(ISNUMBER(VALUE(RIGHT(C12, 1))), "", RIGHT(C12, 1)), _xlpm.NewNum, IF(_xlpm.Num<=18, _xlpm.Num+18, _xlpm.Num-18), _xlpm.NewLetter, IF(_xlpm.Letter="L", "R", IF(_xlpm.Letter="R", "L", _xlpm.Letter)), TEXT(_xlpm.NewNum, "00") & _xlpm.NewLetter )) -> 25 | F12: =IF(D12="", "", IF(D12<=180, D12+180, D12-180)) -> 252 | O12: ENBR | P12: 17 | Q12: 2826 | R12: 2826 | S12: 3119 | T12: 2557 | U12: =TRIM(O12) & TRIM(P12) -> ENBR17
A13: ENHF | B13: 263 | C13: 04 | D13: 42 | E13: =IF(C13="", "", _xlfn.LET( _xlpm.Num, VALUE(LEFT(C13, 2)), _xlpm.Letter, IF(ISNUMBER(VALUE(RIGHT(C13, 1))), "", RIGHT(C13, 1)), _xlpm.NewNum, IF(_xlpm.Num<=18, _xlpm.Num+18, _xlpm.Num-18), _xlpm.NewLetter, IF(_xlpm.Letter="L", "R", IF(_xlpm.Letter="R", "L", _xlpm.Letter)), TEXT(_xlpm.NewNum, "00") & _xlpm.NewLetter )) -> 22 | F13: =IF(D13="", "", IF(D13<=180, D13+180, D13-180)) -> 222 | O13: ENBR | P13: 35 | Q13: 2795 | R13: 2795 | S13: 3095 | T13: 2525 | U13: =TRIM(O13) & TRIM(P13) -> ENBR35
A14: ENEV | B14: 85 | C14: 17 | D14: 168 | E14: =IF(C14="", "", _xlfn.LET( _xlpm.Num, VALUE(LEFT(C14, 2)), _xlpm.Letter, IF(ISNUMBER(VALUE(RIGHT(C14, 1))), "", RIGHT(C14, 1)), _xlpm.NewNum, IF(_xlpm.Num<=18, _xlpm.Num+18, _xlpm.Num-18), _xlpm.NewLetter, IF(_xlpm.Letter="L", "R", IF(_xlpm.Letter="R", "L", _xlpm.Letter)), TEXT(_xlpm.NewNum, "00") & _xlpm.NewLetter )) -> 35 | F14: =IF(D14="", "", IF(D14<=180, D14+180, D14-180)) -> 348 | O14: ENBS | P14: 03 | Q14: 940 | R14: 940 | S14: 1120 | T14: 940 | U14: =TRIM(O14) & TRIM(P14) -> ENBS03
A15: ENHK | B15: 23 | C15: 11 | D15: 107 | E15: =IF(C15="", "", _xlfn.LET( _xlpm.Num, VALUE(LEFT(C15, 2)), _xlpm.Letter, IF(ISNUMBER(VALUE(RIGHT(C15, 1))), "", RIGHT(C15, 1)), _xlpm.NewNum, IF(_xlpm.Num<=18, _xlpm.Num+18, _xlpm.Num-18), _xlpm.NewLetter, IF(_xlpm.Letter="L", "R", IF(_xlpm.Letter="R", "L", _xlpm.Letter)), TEXT(_xlpm.NewNum, "00") & _xlpm.NewLetter )) -> 29 | F15: =IF(D15="", "", IF(D15<=180, D15+180, D15-180)) -> 287 | O15: ENBS | P15: 21 | Q15: 895 | R15: 895 | S15: 1120 | T15: 895 | U15: =TRIM(O15) & TRIM(P15) -> ENBS21
A16: ENHD | B16: 87 | C16: 13 | D16: 133 | E16: =IF(C16="", "", _xlfn.LET( _xlpm.Num, VALUE(LEFT(C16, 2)), _xlpm.Letter, IF(ISNUMBER(VALUE(RIGHT(C16, 1))), "", RIGHT(C16, 1)), _xlpm.NewNum, IF(_xlpm.Num<=18, _xlpm.Num+18, _xlpm.Num-18), _xlpm.NewLetter, IF(_xlpm.Letter="L", "R", IF(_xlpm.Letter="R", "L", _xlpm.Letter)), TEXT(_xlpm.NewNum, "00") & _xlpm.NewLetter )) -> 31 | F16: =IF(D16="", "", IF(D16<=180, D16+180, D16-180)) -> 313 | O16: ENBV | P16: 06 | Q16: 879 | R16: 879 | S16: 1059 | T16: 830 | U16: =TRIM(O16) & TRIM(P16) -> ENBV06
A17: ENHV | B17: 45 | C17: 08 | D17: 77 | E17: =IF(C17="", "", _xlfn.LET( _xlpm.Num, VALUE(LEFT(C17, 2)), _xlpm.Letter, IF(ISNUMBER(VALUE(RIGHT(C17, 1))), "", RIGHT(C17, 1)), _xlpm.NewNum, IF(_xlpm.Num<=18, _xlpm.Num+18, _xlpm.Num-18), _xlpm.NewLetter, IF(_xlpm.Letter="L", "R", IF(_xlpm.Letter="R", "L", _xlpm.Letter)), TEXT(_xlpm.NewNum, "00") & _xlpm.NewLetter )) -> 26 | F17: =IF(D17="", "", IF(D17<=180, D17+180, D17-180)) -> 257 | O17: ENBV | P17: 24 | Q17: 890 | R17: 890 | S17: 1070 | T17: 830 | U17: =TRIM(O17) & TRIM(P17) -> ENBV24
A18: ENEG | B18: 653 | C18: 04 | D18: 36 | E18: =IF(C18="", "", _xlfn.LET( _xlpm.Num, VALUE(LEFT(C18, 2)), _xlpm.Letter, IF(ISNUMBER(VALUE(RIGHT(C18, 1))), "", RIGHT(C18, 1)), _xlpm.NewNum, IF(_xlpm.Num<=18, _xlpm.Num+18, _xlpm.Num-18), _xlpm.NewLetter, IF(_xlpm.Letter="L", "R", IF(_xlpm.Letter="R", "L", _xlpm.Letter)), TEXT(_xlpm.NewNum, "00") & _xlpm.NewLetter )) -> 22 | F18: =IF(D18="", "", IF(D18<=180, D18+180, D18-180)) -> 216 | O18: ENCN | P18: 03 | Q18: 1987 | R18: 1987 | S18: 2160 | T18: 1920 | U18: =TRIM(O18) & TRIM(P18) -> ENCN03
A19: ENKR | B19: 285 | C19: 05 | D19: 53 | E19: =IF(C19="", "", _xlfn.LET( _xlpm.Num, VALUE(LEFT(C19, 2)), _xlpm.Letter, IF(ISNUMBER(VALUE(RIGHT(C19, 1))), "", RIGHT(C19, 1)), _xlpm.NewNum, IF(_xlpm.Num<=18, _xlpm.Num+18, _xlpm.Num-18), _xlpm.NewLetter, IF(_xlpm.Letter="L", "R", IF(_xlpm.Letter="R", "L", _xlpm.Letter)), TEXT(_xlpm.NewNum, "00") & _xlpm.NewLetter )) -> 23 | F19: =IF(D19="", "", IF(D19<=180, D19+180, D19-180)) -> 233 | O19: ENCN | P19: 21 | Q19: 1969 | R19: 1969 | S19: 2144 | T19: 1870 | U19: =TRIM(O19) & TRIM(P19) -> ENCN21
A20: ENKJ | B20: 354 | C20: 12 | D20: 118 | E20: =IF(C20="", "", _xlfn.LET( _xlpm.Num, VALUE(LEFT(C20, 2)), _xlpm.Letter, IF(ISNUMBER(VALUE(RIGHT(C20, 1))), "", RIGHT(C20, 1)), _xlpm.NewNum, IF(_xlpm.Num<=18, _xlpm.Num+18, _xlpm.Num-18), _xlpm.NewLetter, IF(_xlpm.Letter="L", "R", IF(_xlpm.Letter="R", "L", _xlpm.Letter)), TEXT(_xlpm.NewNum, "00") & _xlpm.NewLetter )) -> 30 | F20: =IF(D20="", "", IF(D20<=180, D20+180, D20-180)) -> 298 | O20: ENDU | P20: 10 | Q20: 2443 | R20: 2443 | S20: 2443 | T20: 2001 | U20: =TRIM(O20) & TRIM(P20) -> ENDU10
A21: ENCN | B21: 57 | C21: 03 | D21: 31 | E21: =IF(C21="", "", _xlfn.LET( _xlpm.Num, VALUE(LEFT(C21, 2)), _xlpm.Letter, IF(ISNUMBER(VALUE(RIGHT(C21, 1))), "", RIGHT(C21, 1)), _xlpm.NewNum, IF(_xlpm.Num<=18, _xlpm.Num+18, _xlpm.Num-18), _xlpm.NewLetter, IF(_xlpm.Letter="L", "R", IF(_xlpm.Letter="R", "L", _xlpm.Letter)), TEXT(_xlpm.NewNum, "00") & _xlpm.NewLetter )) -> 21 | F21: =IF(D21="", "", IF(D21<=180, D21+180, D21-180)) -> 211 | O21: ENDU | P21: 28 | Q21: 2443 | R21: 2443 | S21: 2443 | T21: 2443 | U21: =TRIM(O21) & TRIM(P21) -> ENDU28
A22: ENKB | B22: 205 | C22: 07 | D22: 68 | E22: =IF(C22="", "", _xlfn.LET( _xlpm.Num, VALUE(LEFT(C22, 2)), _xlpm.Letter, IF(ISNUMBER(VALUE(RIGHT(C22, 1))), "", RIGHT(C22, 1)), _xlpm.NewNum, IF(_xlpm.Num<=18, _xlpm.Num+18, _xlpm.Num-18), _xlpm.NewLetter, IF(_xlpm.Letter="L", "R", IF(_xlpm.Letter="R", "L", _xlpm.Letter)), TEXT(_xlpm.NewNum, "00") & _xlpm.NewLetter )) -> 25 | F22: =IF(D22="", "", IF(D22<=180, D22+180, D22-180)) -> 248 | O22: ENEV | P22: 17 | Q22: 2812 | R22: 2812 | S22: 3092 | T22: 2718 | U22: =TRIM(O22) & TRIM(P22) -> ENEV17
A23: ENNA | B23: 26 | C23: 16 | D23: 161 | E23: =IF(C23="", "", _xlfn.LET( _xlpm.Num, VALUE(LEFT(C23, 2)), _xlpm.Letter, IF(ISNUMBER(VALUE(RIGHT(C23, 1))), "", RIGHT(C23, 1)), _xlpm.NewNum, IF(_xlpm.Num<=18, _xlpm.Num+18, _xlpm.Num-18), _xlpm.NewLetter, IF(_xlpm.Letter="L", "R", IF(_xlpm.Letter="R", "L", _xlpm.Letter)), TEXT(_xlpm.NewNum, "00") & _xlpm.NewLetter )) -> 34 | F23: =IF(D23="", "", IF(D23<=180, D23+180, D23-180)) -> 341 | O23: ENEV | P23: 35 | Q23: 2812 | R23: 2812 | S23: 3050 | T23: 2752 | U23: =TRIM(O23) & TRIM(P23) -> ENEV35
A24: ENLK | B24: 80 | C24: 02 | D24: 22 | E24: =IF(C24="", "", _xlfn.LET( _xlpm.Num, VALUE(LEFT(C24, 2)), _xlpm.Letter, IF(ISNUMBER(VALUE(RIGHT(C24, 1))), "", RIGHT(C24, 1)), _xlpm.NewNum, IF(_xlpm.Num<=18, _xlpm.Num+18, _xlpm.Num-18), _xlpm.NewLetter, IF(_xlpm.Letter="L", "R", IF(_xlpm.Letter="R", "L", _xlpm.Letter)), TEXT(_xlpm.NewNum, "00") & _xlpm.NewLetter )) -> 20 | F24: =IF(D24="", "", IF(D24<=180, D24+180, D24-180)) -> 202 | O24: ENFL | P24: 07 | Q24: 1199 | R24: 1199 | S24: 1199 | T24: 1199 | U24: =TRIM(O24) & TRIM(P24) -> ENFL07
A25: ENMH | B25: 43 | C25: 17 | D25: 167 | E25: =IF(C25="", "", _xlfn.LET( _xlpm.Num, VALUE(LEFT(C25, 2)), _xlpm.Letter, IF(ISNUMBER(VALUE(RIGHT(C25, 1))), "", RIGHT(C25, 1)), _xlpm.NewNum, IF(_xlpm.Num<=18, _xlpm.Num+18, _xlpm.Num-18), _xlpm.NewLetter, IF(_xlpm.Letter="L", "R", IF(_xlpm.Letter="R", "L", _xlpm.Letter)), TEXT(_xlpm.NewNum, "00") & _xlpm.NewLetter )) -> 35 | F25: =IF(D25="", "", IF(D25<=180, D25+180, D25-180)) -> 347 | O25: ENFL | P25: 25 | Q25: 1199 | R25: 1199 | S25: 1199 | T25: 1199 | U25: =TRIM(O25) & TRIM(P25) -> ENFL25
A26: ENRA | B26: 230 | C26: 13 | D26: 132 | E26: =IF(C26="", "", _xlfn.LET( _xlpm.Num, VALUE(LEFT(C26, 2)), _xlpm.Letter, IF(ISNUMBER(VALUE(RIGHT(C26, 1))), "", RIGHT(C26, 1)), _xlpm.NewNum, IF(_xlpm.Num<=18, _xlpm.Num+18, _xlpm.Num-18), _xlpm.NewLetter, IF(_xlpm.Letter="L", "R", IF(_xlpm.Letter="R", "L", _xlpm.Letter)), TEXT(_xlpm.NewNum, "00") & _xlpm.NewLetter )) -> 31 | F26: =IF(D26="", "", IF(D26<=180, D26+180, D26-180)) -> 312 | O26: ENGM | P26: 01L | Q26: 3600 | R26: 3600 | S26: 3600 | T26: 3600 | U26: =TRIM(O26) & TRIM(P26) -> ENGM01L
A27: ENML | B27: 10 | C27: 07 | D27: 69 | E27: =IF(C27="", "", _xlfn.LET( _xlpm.Num, VALUE(LEFT(C27, 2)), _xlpm.Letter, IF(ISNUMBER(VALUE(RIGHT(C27, 1))), "", RIGHT(C27, 1)), _xlpm.NewNum, IF(_xlpm.Num<=18, _xlpm.Num+18, _xlpm.Num-18), _xlpm.NewLetter, IF(_xlpm.Letter="L", "R", IF(_xlpm.Letter="R", "L", _xlpm.Letter)), TEXT(_xlpm.NewNum, "00") & _xlpm.NewLetter )) -> 25 | F27: =IF(D27="", "", IF(D27<=180, D27+180, D27-180)) -> 249 | O27: ENGM | P27: 19R | Q27: 3600 | R27: 3600 | S27: 3600 | T27: 3600 | U27: =TRIM(O27) & TRIM(P27) -> ENGM19R
A28: ENMS | B28: 241 | C28: 15 | D28: 155 | E28: =IF(C28="", "", _xlfn.LET( _xlpm.Num, VALUE(LEFT(C28, 2)), _xlpm.Letter, IF(ISNUMBER(VALUE(RIGHT(C28, 1))), "", RIGHT(C28, 1)), _xlpm.NewNum, IF(_xlpm.Num<=18, _xlpm.Num+18, _xlpm.Num-18), _xlpm.NewLetter, IF(_xlpm.Letter="L", "R", IF(_xlpm.Letter="R", "L", _xlpm.Letter)), TEXT(_xlpm.NewNum, "00") & _xlpm.NewLetter )) -> 33 | F28: =IF(D28="", "", IF(D28<=180, D28+180, D28-180)) -> 335 | O28: ENGM | P28: 01R | Q28: 2950 | R28: 2950 | S28: 2950 | T28: 2950 | U28: =TRIM(O28) & TRIM(P28) -> ENGM01R
A29: ENNM | B29: 8 | C29: 07 | D29: 70 | E29: =IF(C29="", "", _xlfn.LET( _xlpm.Num, VALUE(LEFT(C29, 2)), _xlpm.Letter, IF(ISNUMBER(VALUE(RIGHT(C29, 1))), "", RIGHT(C29, 1)), _xlpm.NewNum, IF(_xlpm.Num<=18, _xlpm.Num+18, _xlpm.Num-18), _xlpm.NewLetter, IF(_xlpm.Letter="L", "R", IF(_xlpm.Letter="R", "L", _xlpm.Letter)), TEXT(_xlpm.NewNum, "00") & _xlpm.NewLetter )) -> 25 | F29: =IF(D29="", "", IF(D29<=180, D29+180, D29-180)) -> 250 | O29: ENGM | P29: 19L | Q29: 2950 | R29: 2950 | S29: 3350 | T29: 2950 | U29: =TRIM(O29) & TRIM(P29) -> ENGM19L
A30: ENNO | B30: 62 | C30: 12 | D30: 124 | E30: =IF(C30="", "", _xlfn.LET( _xlpm.Num, VALUE(LEFT(C30, 2)), _xlpm.Letter, IF(ISNUMBER(VALUE(RIGHT(C30, 1))), "", RIGHT(C30, 1)), _xlpm.NewNum, IF(_xlpm.Num<=18, _xlpm.Num+18, _xlpm.Num-18), _xlpm.NewLetter, IF(_xlpm.Letter="L", "R", IF(_xlpm.Letter="R", "L", _xlpm.Letter)), TEXT(_xlpm.NewNum, "00") & _xlpm.NewLetter )) -> 30 | F30: =IF(D30="", "", IF(D30<=180, D30+180, D30-180)) -> 304 | O30: ENHD | P30: 13 | Q30: 2061 | R30: 2061 | S30: 2361 | T30: 2000 | U30: =TRIM(O30) & TRIM(P30) -> ENHD13
A31: ENAS | B31: 131 | C31: 12 | D31: 109 | E31: =IF(C31="", "", _xlfn.LET( _xlpm.Num, VALUE(LEFT(C31, 2)), _xlpm.Letter, IF(ISNUMBER(VALUE(RIGHT(C31, 1))), "", RIGHT(C31, 1)), _xlpm.NewNum, IF(_xlpm.Num<=18, _xlpm.Num+18, _xlpm.Num-18), _xlpm.NewLetter, IF(_xlpm.Letter="L", "R", IF(_xlpm.Letter="R", "L", _xlpm.Letter)), TEXT(_xlpm.NewNum, "00") & _xlpm.NewLetter )) -> 30 | F31: =IF(D31="", "", IF(D31<=180, D31+180, D31-180)) -> 289 | O31: ENHD | P31: 31 | Q31: 2060 | R31: 2060 | S31: 2360 | T31: 2000 | U31: =TRIM(O31) & TRIM(P31) -> ENHD31
A32: ENGM | B32: 682 | C32: 01L | D32: 12 | E32: =IF(C32="", "", _xlfn.LET( _xlpm.Num, VALUE(LEFT(C32, 2)), _xlpm.Letter, IF(ISNUMBER(VALUE(RIGHT(C32, 1))), "", RIGHT(C32, 1)), _xlpm.NewNum, IF(_xlpm.Num<=18, _xlpm.Num+18, _xlpm.Num-18), _xlpm.NewLetter, IF(_xlpm.Letter="L", "R", IF(_xlpm.Letter="R", "L", _xlpm.Letter)), TEXT(_xlpm.NewNum, "00") & _xlpm.NewLetter )) -> 19R | F32: =IF(D32="", "", IF(D32<=180, D32+180, D32-180)) -> 192 | G32: 01R | H32: 12 | I32: =IF(G32="", "", _xlfn.LET( _xlpm.Num, VALUE(LEFT(G32, 2)), _xlpm.Letter, IF(ISNUMBER(VALUE(RIGHT(G32, 1))), "", RIGHT(G32, 1)), _xlpm.NewNum, IF(_xlpm.Num<=18, _xlpm.Num+18, _xlpm.Num-18), _xlpm.NewLetter, IF(_xlpm.Letter="L", "R", IF(_xlpm.Letter="R", "L", _xlpm.Letter)), TEXT(_xlpm.NewNum, "00") & _xlpm.NewLetter )) -> 19L | J32: =IF(H32="", "", IF(H32<=180, H32+180, H32-180)) -> 192 | O32: ENHF | P32: 04 | Q32: 891 | R32: 891 | S32: 891 | T32: 850 | U32: =TRIM(O32) & TRIM(P32) -> ENHF04
A33: ENRE | B33: 828 | C33: 12 | D33: 123 | E33: =IF(C33="", "", _xlfn.LET( _xlpm.Num, VALUE(LEFT(C33, 2)), _xlpm.Letter, IF(ISNUMBER(VALUE(RIGHT(C33, 1))), "", RIGHT(C33, 1)), _xlpm.NewNum, IF(_xlpm.Num<=18, _xlpm.Num+18, _xlpm.Num-18), _xlpm.NewLetter, IF(_xlpm.Letter="L", "R", IF(_xlpm.Letter="R", "L", _xlpm.Letter)), TEXT(_xlpm.NewNum, "00") & _xlpm.NewLetter )) -> 30 | F33: =IF(D33="", "", IF(D33<=180, D33+180, D33-180)) -> 303 | I33: =IF(G33="", "", _xlfn.LET( _xlpm.Num, VALUE(LEFT(G33, 2)), _xlpm.Letter, IF(ISNUMBER(VALUE(RIGHT(G33, 1))), "", RIGHT(G33, 1)), _xlpm.NewNum, IF(_xlpm.Num<=18, _xlpm.Num+18, _xlpm.Num-18), _xlpm.NewLetter, IF(_xlpm.Letter="L", "R", IF(_xlpm.Letter="R", "L", _xlpm.Letter)), TEXT(_xlpm.NewNum, "00") & _xlpm.NewLetter )) | J33: =IF(H33="", "", IF(H33<=180, H33+180, H33-180)) | O33: ENHF | P33: 22 | Q33: 867 | R33: 867 | S33: 867 | T33: 824 | U33: =TRIM(O33) & TRIM(P33) -> ENHF22
A34: ENRY | B34: 174 | C34: 12 | D34: 113 | E34: =IF(C34="", "", _xlfn.LET( _xlpm.Num, VALUE(LEFT(C34, 2)), _xlpm.Letter, IF(ISNUMBER(VALUE(RIGHT(C34, 1))), "", RIGHT(C34, 1)), _xlpm.NewNum, IF(_xlpm.Num<=18, _xlpm.Num+18, _xlpm.Num-18), _xlpm.NewLetter, IF(_xlpm.Letter="L", "R", IF(_xlpm.Letter="R", "L", _xlpm.Letter)), TEXT(_xlpm.NewNum, "00") & _xlpm.NewLetter )) -> 30 | F34: =IF(D34="", "", IF(D34<=180, D34+180, D34-180)) -> 293 | I34: =IF(G34="", "", _xlfn.LET( _xlpm.Num, VALUE(LEFT(G34, 2)), _xlpm.Letter, IF(ISNUMBER(VALUE(RIGHT(G34, 1))), "", RIGHT(G34, 1)), _xlpm.NewNum, IF(_xlpm.Num<=18, _xlpm.Num+18, _xlpm.Num-18), _xlpm.NewLetter, IF(_xlpm.Letter="L", "R", IF(_xlpm.Letter="R", "L", _xlpm.Letter)), TEXT(_xlpm.NewNum, "00") & _xlpm.NewLetter )) | J34: =IF(H34="", "", IF(H34<=180, H34+180, H34-180)) | O34: ENHK | P34: 11 | Q34: 859 | R34: 859 | S34: 1039 | T34: 819 | U34: =TRIM(O34) & TRIM(P34) -> ENHK11
A35: ENRO | B35: 2054 | C35: 13 | D35: 132 | E35: =IF(C35="", "", _xlfn.LET( _xlpm.Num, VALUE(LEFT(C35, 2)), _xlpm.Letter, IF(ISNUMBER(VALUE(RIGHT(C35, 1))), "", RIGHT(C35, 1)), _xlpm.NewNum, IF(_xlpm.Num<=18, _xlpm.Num+18, _xlpm.Num-18), _xlpm.NewLetter, IF(_xlpm.Letter="L", "R", IF(_xlpm.Letter="R", "L", _xlpm.Letter)), TEXT(_xlpm.NewNum, "00") & _xlpm.NewLetter )) -> 31 | F35: =IF(D35="", "", IF(D35<=180, D35+180, D35-180)) -> 312 | I35: =IF(G35="", "", _xlfn.LET( _xlpm.Num, VALUE(LEFT(G35, 2)), _xlpm.Letter, IF(ISNUMBER(VALUE(RIGHT(G35, 1))), "", RIGHT(G35, 1)), _xlpm.NewNum, IF(_xlpm.Num<=18, _xlpm.Num+18, _xlpm.Num-18), _xlpm.NewLetter, IF(_xlpm.Letter="L", "R", IF(_xlpm.Letter="R", "L", _xlpm.Letter)), TEXT(_xlpm.NewNum, "00") & _xlpm.NewLetter )) | J35: =IF(H35="", "", IF(H35<=180, H35+180, H35-180)) | O35: ENHK | P35: 29 | Q35: 909 | R35: 909 | S35: 1228 | T35: 799 | U35: =TRIM(O35) & TRIM(P35) -> ENHK29
A36: ENRM | B36: 15 | C36: 04 | D36: 37 | E36: =IF(C36="", "", _xlfn.LET( _xlpm.Num, VALUE(LEFT(C36, 2)), _xlpm.Letter, IF(ISNUMBER(VALUE(RIGHT(C36, 1))), "", RIGHT(C36, 1)), _xlpm.NewNum, IF(_xlpm.Num<=18, _xlpm.Num+18, _xlpm.Num-18), _xlpm.NewLetter, IF(_xlpm.Letter="L", "R", IF(_xlpm.Letter="R", "L", _xlpm.Letter)), TEXT(_xlpm.NewNum, "00") & _xlpm.NewLetter )) -> 22 | F36: =IF(D36="", "", IF(D36<=180, D36+180, D36-180)) -> 217 | I36: =IF(G36="", "", _xlfn.LET( _xlpm.Num, VALUE(LEFT(G36, 2)), _xlpm.Letter, IF(ISNUMBER(VALUE(RIGHT(G36, 1))), "", RIGHT(G36, 1)), _xlpm.NewNum, IF(_xlpm.Num<=18, _xlpm.Num+18, _xlpm.Num-18), _xlpm.NewLetter, IF(_xlpm.Letter="L", "R", IF(_xlpm.Letter="R", "L", _xlpm.Letter)), TEXT(_xlpm.NewNum, "00") & _xlpm.NewLetter )) | J36: =IF(H36="", "", IF(H36<=180, H36+180, H36-180)) | O36: ENHV | P36: 08 | Q36: 860 | R36: 860 | S36: 860 | T36: 800 | U36: =TRIM(O36) & TRIM(P36) -> ENHV08
A37: ENRS | B37: 9 | C37: 02 | D37: 23 | E37: =IF(C37="", "", _xlfn.LET( _xlpm.Num, VALUE(LEFT(C37, 2)), _xlpm.Letter, IF(ISNUMBER(VALUE(RIGHT(C37, 1))), "", RIGHT(C37, 1)), _xlpm.NewNum, IF(_xlpm.Num<=18, _xlpm.Num+18, _xlpm.Num-18), _xlpm.NewLetter, IF(_xlpm.Letter="L", "R", IF(_xlpm.Letter="R", "L", _xlpm.Letter)), TEXT(_xlpm.NewNum, "00") & _xlpm.NewLetter )) -> 20 | F37: =IF(D37="", "", IF(D37<=180, D37+180, D37-180)) -> 203 | I37: =IF(G37="", "", _xlfn.LET( _xlpm.Num, VALUE(LEFT(G37, 2)), _xlpm.Letter, IF(ISNUMBER(VALUE(RIGHT(G37, 1))), "", RIGHT(G37, 1)), _xlpm.NewNum, IF(_xlpm.Num<=18, _xlpm.Num+18, _xlpm.Num-18), _xlpm.NewLetter, IF(_xlpm.Letter="L", "R", IF(_xlpm.Letter="R", "L", _xlpm.Letter)), TEXT(_xlpm.NewNum, "00") & _xlpm.NewLetter )) | J37: =IF(H37="", "", IF(H37<=180, H37+180, H37-180)) | O37: ENHV | P37: 26 | Q37: 860 | R37: 860 | S37: 860 | T37: 800 | U37: =TRIM(O37) & TRIM(P37) -> ENHV26
A38: ENSD | B38: 196 | C38: 08 | D38: 83 | E38: =IF(C38="", "", _xlfn.LET( _xlpm.Num, VALUE(LEFT(C38, 2)), _xlpm.Letter, IF(ISNUMBER(VALUE(RIGHT(C38, 1))), "", RIGHT(C38, 1)), _xlpm.NewNum, IF(_xlpm.Num<=18, _xlpm.Num+18, _xlpm.Num-18), _xlpm.NewLetter, IF(_xlpm.Letter="L", "R", IF(_xlpm.Letter="R", "L", _xlpm.Letter)), TEXT(_xlpm.NewNum, "00") & _xlpm.NewLetter )) -> 26 | F38: =IF(D38="", "", IF(D38<=180, D38+180, D38-180)) -> 263 | I38: =IF(G38="", "", _xlfn.LET( _xlpm.Num, VALUE(LEFT(G38, 2)), _xlpm.Letter, IF(ISNUMBER(VALUE(RIGHT(G38, 1))), "", RIGHT(G38, 1)), _xlpm.NewNum, IF(_xlpm.Num<=18, _xlpm.Num+18, _xlpm.Num-18), _xlpm.NewLetter, IF(_xlpm.Letter="L", "R", IF(_xlpm.Letter="R", "L", _xlpm.Letter)), TEXT(_xlpm.NewNum, "00") & _xlpm.NewLetter )) | J38: =IF(H38="", "", IF(H38<=180, H38+180, H38-180)) | O38: ENKB | P38: 07 | Q38: 2083 | R38: 2083 | S38: 2383 | T38: 2001 | U38: =TRIM(O38) & TRIM(P38) -> ENKB07
A39: ENTO | B39: 286 | C39: 18 | D39: 176 | E39: =IF(C39="", "", _xlfn.LET( _xlpm.Num, VALUE(LEFT(C39, 2)), _xlpm.Letter, IF(ISNUMBER(VALUE(RIGHT(C39, 1))), "", RIGHT(C39, 1)), _xlpm.NewNum, IF(_xlpm.Num<=18, _xlpm.Num+18, _xlpm.Num-18), _xlpm.NewLetter, IF(_xlpm.Letter="L", "R", IF(_xlpm.Letter="R", "L", _xlpm.Letter)), TEXT(_xlpm.NewNum, "00") & _xlpm.NewLetter )) -> 36 | F39: =IF(D39="", "", IF(D39<=180, D39+180, D39-180)) -> 356 | I39: =IF(G39="", "", _xlfn.LET( _xlpm.Num, VALUE(LEFT(G39, 2)), _xlpm.Letter, IF(ISNUMBER(VALUE(RIGHT(G39, 1))), "", RIGHT(G39, 1)), _xlpm.NewNum, IF(_xlpm.Num<=18, _xlpm.Num+18, _xlpm.Num-18), _xlpm.NewLetter, IF(_xlpm.Letter="L", "R", IF(_xlpm.Letter="R", "L", _xlpm.Letter)), TEXT(_xlpm.NewNum, "00") & _xlpm.NewLetter )) | J39: =IF(H39="", "", IF(H39<=180, H39+180, H39-180)) | O39: ENKB | P39: 25 | Q39: 2071 | R39: 2071 | S39: 2371 | T39: 2001 | U39: =TRIM(O39) & TRIM(P39) -> ENKB25
A40: ENST | B40: 58 | C40: 02 | D40: 20 | E40: =IF(C40="", "", _xlfn.LET( _xlpm.Num, VALUE(LEFT(C40, 2)), _xlpm.Letter, IF(ISNUMBER(VALUE(RIGHT(C40, 1))), "", RIGHT(C40, 1)), _xlpm.NewNum, IF(_xlpm.Num<=18, _xlpm.Num+18, _xlpm.Num-18), _xlpm.NewLetter, IF(_xlpm.Letter="L", "R", IF(_xlpm.Letter="R", "L", _xlpm.Letter)), TEXT(_xlpm.NewNum, "00") & _xlpm.NewLetter )) -> 20 | F40: =IF(D40="", "", IF(D40<=180, D40+180, D40-180)) -> 200 | I40: =IF(G40="", "", _xlfn.LET( _xlpm.Num, VALUE(LEFT(G40, 2)), _xlpm.Letter, IF(ISNUMBER(VALUE(RIGHT(G40, 1))), "", RIGHT(G40, 1)), _xlpm.NewNum, IF(_xlpm.Num<=18, _xlpm.Num+18, _xlpm.Num-18), _xlpm.NewLetter, IF(_xlpm.Letter="L", "R", IF(_xlpm.Letter="R", "L", _xlpm.Letter)), TEXT(_xlpm.NewNum, "00") & _xlpm.NewLetter )) | J40: =IF(H40="", "", IF(H40<=180, H40+180, H40-180)) | O40: ENKJ | P40: 12 | Q40: 1350 | R40: 1350 | S40: 1350 | T40: 1350 | U40: =TRIM(O40) & TRIM(P40) -> ENKJ12
...

Sheet AC REG
A2: A (Registration) | B2: B (Weight) | C2: C (Moment) | D2: D (extra)
A3: LN-TRA | B3: 1993.6 | C3: 75870.2
A4: LN-TRB | B4: 2020.3 | C4: 78756.2
A5: LN-TRC | B5: 2031.1 | C5: 77121.6
A6: LN-TRD | B6: 2024.5 | C6: 76587.7
A7: LN-TRE | B7: 2038.5 | C7: 78989.1 | D7: 22.7
